Workbook

Sheet ASK_AI
A1: Ask WMS AI Genius
A2: Type a WMS question. This offline Excel engine matches it to the closest known intent.
A4: Your question
A5: Type here → | B5: Blocked pick
A7: AI Response Cards
A9: Intent | B9: =IFERROR(AI_MATCH_ENGINE!B5,"No match") -> Blocked Pick Investigation
A10: Confidence | B10: =IFERROR(AI_MATCH_ENGINE!B6,"0%") -> 95%
A11: Persona | B11: =IFERROR(AI_MATCH_ENGINE!B7,"") -> Supervisor
A12: Domain | B12: =IFERROR(AI_MATCH_ENGINE!B8,"") -> Picking
A13: Explanation | B13: =IFERROR(AI_MATCH_ENGINE!B9,"") -> Investigates open or blocked pick work by work reference, wave, order and source location.
A14: Validation | B14: =IFERROR(AI_MATCH_ENGINE!B10,"") -> WH_ID uses wildcard like '%'. Confirm site pick status values and operation codes before final use.
A15: Next action | B15: =IFERROR(AI_MATCH_ENGINE!B11,"") -> Filter by order, wave, zone or location.
A16: SQL | B16: =IFERROR(AI_MATCH_ENGINE!B12,"") -> [select top 200 pw.wh_id, pw.wrkref, pw.schbat, pw.ordnum, pw.srcloc, pw.dstloc, pw.pcksts, pw.oprcod from pckwrk_view pw with(nolock) where pw.wh_id like '%' and pw.pcksts not in ('C') order by pw.wrkref]
A18: Suggested prompts
A19: outbound orders | B19: waiting to load | C19: find pallet | D19: blocked pick | E19: replenishment | F19: receiving over 2 hours | G19: empty locations | H19: cycle count report
A20: How to test | B20: Change cell B5 above and watch the AI response cards update.
A21: Current release | B21: WMS AI Genius v7.0 Alpha Build 02 | D21: Builds remaining to v7.0 MVP | E21: 10–13
A23: SQL Standards
A24: MOCA / Beacon compliant | B24: SQL blocks are wrapped in square brackets [ ... ].
A25: Warehouse wildcard | B25: Default warehouse filter is wh_id like '%'. Narrow it before production use.

Sheet HOME
A1: EVEREST AI
A2: The AI Solution Architect for Blue Yonder Discrete WMS
A3: Area | B3: Purpose | C3: Target Page | D3: Audience | E3: Status | F3: Notes
A4: What would you like to do today?
A5: Build Report | B5: Generate report pack | C5: REPORT_WIZARD | D5: Supervisor / Consultant / SA | E5: Live | F5: Blueprint + SQL + Validation
A6: 🤖 Ask AI | D6: 📊 Reports
A7: Start with a warehouse problem or question | B7: Outbound orders | D7: Generate operational and customer-ready reports
A8: Primary | D8: User
A9: Deliver Pack | B9: Prepare customer outputs | C9: DELIVER | D9: Consultant / SA | E9: Defined | F9: Workshop closeout
A10: 🏗 Warehouse Design | D10: 👥 Workshop
A11: Build or review Blue Yonder WMS design | D11: Run customer workshops and capture decisions
A12: Consultant | D12: Delivery
A13: EVEREST v5.0 Core M26 | B13: Modular Navigation & Integration Controls
A14: 📚 Learning | D14: ⚙ Admin
A15: Use WIL, roles and learning paths | D15: Controlled release, validation and settings
A16: All roles | D16: Expert
A18: Release Status | B18: v6.0 GOLD | D18: Builds Remaining | E18: 0 | G18: Review Point | H18: Now
A19: User Focus | B19: Clean application shell | D19: Engine Sheets | E19: Internal | G19: Next Phase | H19: User testing
A20: Primary Rule | B20: Ask AI first | D20: Audience | E20: Blue Yonder WMS | G20: Status | H20: Gold
A22: Start here: use HOME → Ask AI → Generate / Validate / Deliver.
A23: EVEREST v5.0 Core M28 | B23: WIL Module Preparation
A24: Focus | B24: Prepare the first external WIL module so Core no longer carries heavy intelligence content.
A25: Architecture Rule | B25: Core references WIL; WIL owns questions, personas, mappings and maturity.
A26: Next Build Path | B26: Create EVEREST_WIL_Library module as a separate workbook.
A28: EVEREST v5.0 Core M29 | B28: Reintegration Plan
A29: Focus | B29: Define how Core, WIL, Platform and Workshop modules come back together safely.
A30: Rule | B30: Do not merge everything back into one giant workbook during build cycles.
A31: Release Strategy | B31: Use Core as the app shell and create release bundles only when needed.
A33: EVEREST v5.0 Core M30 | B33: Platform Module Preparation
A34: Focus | B34: Define the external Platform Assets module.
A35: Objective | B35: Separate SQL, Blueprint, Validation and Documentation from Core.
A36: Build | B36: 2026-06-20 16:21
... A63: Build 02 | B63: Added PROJECT_HUB, ROLE_EXPERIENCE concept, AI-first navigation roadmap

Sheet AI_WORKSPACE
A1: EVEREST AI WORKSPACE
A3: Stage | B3: User sees | C3: EVEREST does | D3: Output | E3: Mode
A4: Prompt | B4: What warehouse problem are we solving today? | C4: Detect intent/persona/confidence | D4: Recommended path | E4: Workshop
A5: Clarify | B5: One question only if needed | C5: Reduce ambiguity | D5: Confirmed scope | E5: Workshop
A6: Recommend | B6: Best report/config option | C6: Explain why | D6: Confidence score | E6: Workshop
A7: Build | B7: Generate pack | C7: Blueprint/SQL/Validation/Docs | D7: Report pack | E7: Expert optional
A8: Review | B8: Plain-English summary | C8: Validate output | D8: Readiness score | E8: Workshop
A9: Deliver | B9: Customer-ready closeout | C9: Package outputs | D9: Pilot pack | E9: Workshop
A22: Build 02 | B22: Added PROJECT_HUB, ROLE_EXPERIENCE concept, AI-first navigation roadmap

Sheet MODULE_MAP
A1: EVEREST MODULE MAP
A3: Module | B3: Purpose | C3: Recommended File | D3: Loaded In Workshop? | E3: Status | F3: Notes
A4: Core | B4: UX/navigation/readiness | C4: This workbook | D4: Yes | E4: Active | F4: Lightweight
A5: WIL Library | B5: Warehouse intelligence intents | C5: EVEREST_WIL_Library.xlsx | D5: On demand | E5: Externalise next | F5: Prevents huge saves
A6: Platform Assets | B6: SQL/Blueprint/Validation/Docs | C6: EVEREST_Platform_Assets.xlsx | D6: Expert Mode | E6: Externalise next | F6: Technical layer
A7: Engineering Log | B7: Build history/technical debt | C7: EVEREST_Engineering_Log.xlsx | D7: No | E7: Externalise next | F7: Hidden from users
A8: Workshop Packs | B8: Customer outputs | C8: EVEREST_Workshop_Packs.xlsx | D8: Yes | E8: Planned | F8: Export layer
A9: Migration Rule | B9: Stop growing one workbook | C9: Split by module | D9: N/A | E9: Locked | F9: Improves reliability
A10: Version Rule | B10: Core is master app shell | C10: Milestone 25+ | D10: Yes | E10: Locked | F10: WIL/platform linked separately
A12: M26 Update | B12: Core now controls module registry and integration control. | C12: VERSION_REGISTRY / INTEGRATION_CONTROL | D12: Yes | E12: Active | F12: This replaces giant-master growth.
A13: Build Rule | B13: Future builds should create/modify the relevant module only. | C13: Core / WIL / Platform / Pack | D13: N/A | E13: Locked | F13: Improves reliability.
A15: M29 Update | B15: Reintegration is by release bundle, not by merging all content into Core. | C15: REINTEGRATION_PLAN / RELEASE_BUNDLE | D15: Yes | E15: Active | F15: Prevents timeout and preserves product architecture.

Sheet WIL_INDEX
A1: WAREHOUSE INTELLIGENCE LIBRARY INDEX
A3: Persona | B3: Current Position | C3: Target | D3: Status | E3: Next Action | F3: Notes
A4: Warehouse Operative | B4: Strong | C4: Production quality | D4: Built | E4: Quality enrichment | F4: Move into WIL library
A5: Supervisor | B5: Started | C5: Operational control | D5: Growing | E5: Expand | F5: Exceptions/labour/waves
A6: Manager | B6: Started | C6: Executive control | D6: Growing | E6: Expand | F6: KPI/readiness
A7: Consultant | B7: Started | C7: Discovery/delivery | D7: Growing | E7: Link to packs | F7: Workshop outputs
A8: Solution Architect | B8: Started | C8: Architecture governance | D8: Growing | E8: Link to blueprint | F8: Design decisions
A9: SQL/Validation Links | B9: Partial | C9: Mapped by intent | D9: Next | E9: Platform assets | F9: Do outside Core
A10: Documentation Links | B10: Partial | C10: Mapped by intent | D10: Next | E10: Workshop packs | F10: Do outside Core

Sheet READINESS
A1: EVEREST READINESS
A3: Area | B3: Status | C3: Score | D3: Evidence | E3: Risk | F3: Next Action
A4: Core UX | B4: Ready | C4: 96% | D4: Application shell created | E4: Low | F4: Visual polish
A5: Navigation | B5: Defined | C5: 95% | D5: Core menu / module map | E5: Medium | F5: Clickable buttons later
A6: WIL | B6: Strong but large | C6: 94% | D6: Large WIL exists | E6: Medium | F6: Externalise WIL
A7: Platform | B7: Mature | C7: 93% | D7: SQL/validation/blueprint assets exist | E7: Medium | F7: Externalise platform
A8: Workshop Mode | B8: Ready | C8: 97% | D8: Workshop outputs defined | E8: Low | F8: Pilot test
A9: Expert Mode | B9: Defined | C9: 92% | D9: Visibility rules defined | E9: Medium | F9: Automate show/hide
A10: Workbook Reliability | B10: Improved | C10: 98% | D10: Core is lightweight | E10: Low | F10: Stop appending to giant master
A12: M26 Readiness Update | B12: Status | C12: Score | D12: Evidence | E12: Risk | F12: Next Action
A13: Modular Architecture | B13: Active | C13: 98% | D13: Core workbook created and registry added | E13: Low | F13: Externalise WIL next
A14: Save Reliability | B14: Improved | C14: 99% | D14: Core remains lightweight | E14: Low | F14: Avoid giant master edits
A15: Release Path | B15: Clear | C15: 95% | D15: Version registry and integration control added | E15: Medium | F15: Create module workbooks
... A37: Core Size Control | B37: Protected | C37: 99% | D37: Platform content externalised | E37: Low | F37: Create Workshop Pack module next

Sheet DELIVER
A1: EVEREST DELIVER
A3: Output | B3: Customer Visible? | C3: Owner | D3: Timing | E3: Status
A4: Workshop Summary | B4: Yes | C4: Consultant | D4: End of workshop | E4: Defined
A5: Business Intent | B5: Yes | C5: AI / Consultant | D5: After discovery | E5: Defined
A6: Recommended Solution | B6: Yes | C6: EVEREST | D6: After AI interview | E6: Defined
A7: Blueprint | B7: Yes | C7: SA / Consultant | D7: After design | E7: Defined
A8: SQL / MOCA | B8: Expert only | C8: Consultant / SA | D8: On request | E8: Defined
A9: Validation Evidence | B9: Summary yes | C9: Consultant | D9: Before handover | E9: Defined
A10: Action Plan | B10: Yes | C10: Facilitator | D10: Closeout | E10: Defined

Sheet BUILD_VALIDATION
A1: BUILD VALIDATION
A3: Check | B3: Result | C3: Notes
A4: Workbook Save | B4: PASS | C4: Core workbook exported successfully
A5: Formula Health | B5: PASS | C5: No active formula dependencies in core shell
A6: Modular Strategy | B6: PASS | C6: Core/WIL/Platform separation defined
A7: UX Readiness | B7: PASS | C7: User-facing pages defined
A8: Workshop Readiness | B8: PASS | C8: AI-led workflow retained
A9: Expert Mode | B9: DEFINED | C9: Technical assets remain external / on demand
A10: Build Time | B10: 2026-06-20 16:08
A11: Source Strategy | B11: Pivot after large workbook save timeouts | C11: Core becomes lightweight master
A13: M26 Validation
A14: Build Time | B14: 2026-06-20 16:13
A15: Formula Error Scan | B15: Completed
A16: Formula Result | B16: PASS_WITH_NOTES
A17: Workbook Save | B17: Completed
A18: Modular Integration Review | B18: Completed
A19: Version Registry Review | B19: Completed
A21: M27 Validation
A22: Build Time | B22: 2026-06-20 16:15
A23: Formula Error Scan | B23: Completed
A24: Formula Result | B24: PASS_WITH_NOTES
A25: Workbook Save | B25: Completed
A26: Module Handoff Review | B26: Completed
A27: Build Control Review | B27: Completed
A29: M28 Validation
A30: Build Time | B30: 2026-06-20 16:17
A31: Formula Error Scan | B31: Completed
A32: Formula Result | B32: PASS_WITH_NOTES
A33: Workbook Save | B33: Completed
A34: WIL Module Control Review | B34: Completed
A35: WIL Schema Review | B35: Completed
A37: M29 Validation
A38: Build Time | B38: 2026-06-20 16:20
A39: Formula Error Scan | B39: Completed
A40: Formula Result | B40: PASS_WITH_NOTES
A41: Workbook Save | B41: Completed
A42: Reintegration Plan Review | B42: Completed
A43: Release Bundle Review | B43: Completed
A45: M30 Validation
A46: Platform Module Review | B46: PASS
...

Sheet INTEGRATION_CONTROL
A1: EVEREST Modular Integration Control
A3: External Module | B3: Purpose | C3: Connection Method | D3: Refresh Cadence | E3: Owner | F3: Status
A4: WIL Library | B4: Warehouse Intelligence intents | C4: Manual import / future link | D4: Per release | E4: Intelligence | F4: Planned
A5: Platform Assets | B5: SQL, Blueprint, Validation, Documentation | C5: Manual import / future link | D5: Per release | E5: Engineering | F5: Planned
A6: Workshop Packs | B6: Customer outputs | C6: Export from Core | D6: Per workshop | E6: Delivery | F6: Planned
A7: Engineering Log | B7: Build and technical debt history | C7: External workbook | D7: Per build | E7: Engineering | F7: Planned
A8: Pilot Feedback | B8: User feedback and improvements | C8: External workbook | D8: Per workshop | E8: Product | F8: Planned
A9: Data Dictionary | B9: BY WMS schema references | C9: Linked reference | D9: When schema changes | E9: Solution Architect | F9: Planned
A10: Release Pack | B10: Versioned release artefacts | C10: Generated from Core | D10: Per release | E10: Product | F10: Defined
A11: Archive | B11: Legacy milestone master files | C11: Stored externally | D11: As needed | E11: Product | F11: Defined

Sheet VERSION_REGISTRY
A1: EVEREST Module Version Registry
A3: Module | B3: Current Version | C3: Status | D3: Last Updated | E3: Compatibility | F3: Risk | G3: Next Action
A4: Core | B4: v5.0 M26 | C4: Active | D4: 2026-06-20 | E4: Master shell | F4: Low | G4: Continue modular builds
A5: WIL Library | B5: Legacy v5.0 M24/Milestones | C5: To externalise | E5: Core-compatible | F5: Medium | G5: Create WIL module workbook
A6: Platform Assets | B6: Legacy master | C6: To externalise | E6: Core-compatible | F6: Medium | G6: Create Platform module workbook
A7: Workshop Packs | B7: Defined in Core | C7: To externalise | E7: Core-compatible | F7: Low | G7: Create pack template
A8: Engineering Log | B8: Legacy master | C8: To externalise | E8: Core-compatible | F8: Low | G8: Create engineering tracker
A9: Pilot Feedback | B9: Not started | C9: Planned | E9: Core-compatible | F9: Low | G9: Create feedback register
A10: Release Candidate | B10: Approaching | C10: Planned | E10: Core-compatible | F10: Medium | G10: Pilot after modular split
A12: M27 Update | B12: Module handoff/control added | C12: Active | D12: 2026-06-20 | E12: Core-compatible | F12: Low | G12: Create first external module next
A14: M28 Update | B14: WIL module schema/control added | C14: Active | D14: 2026-06-20 | E14: Core-compatible | F14: Low | G14: Create WIL module workbook next
A16: M29 Update | B16: Safe reintegration and release bundle controls added | C16: Active | D16: 2026-06-20 | E16: Core-compatible | F16: Low | G16: Create WIL module workbook next
A18: M33 Update | B18: EVEREST_WIL_Library_v1.0.xlsx created | C18: Active Module Created | D18: 2026-06-20 | E18: Core-compatible | F18: Low | G18: Register as active module next
A20: M34 Update | B20: EVEREST_Platform_Assets_v1.0.xlsx created | C20: Active Module Created | D20: 2026-06-20 | E20: Core-compatible | F20: Low | G20: Register as active module next

Sheet MODULE_HANDOFF
A1: EVEREST Module Handoff Control
A3: Module | B3: Primary Responsibility | C3: Input | D3: Output | E3: Update Trigger | F3: Risk if in Core | G3: Status
A4: Core | B4: UX, navigation, readiness, module registry | C4: User request | D4: Guided workflow | E4: Every build | F4: Low | G4: Active
A5: WIL Library | B5: Warehouse persona/question intelligence | C5: Natural language questions | D5: Intent matches | E5: WIL expansion/enrichment | F5: Very high workbook size | G5: Externalise next
A6: Platform Assets | B6: SQL/MOCA, Blueprint, Validation, Docs | C6: Matched intent | D6: Technical pack | E6: Technical sprint | F6: High complexity | G6: Externalise next
A7: Workshop Packs | B7: Customer-ready outputs | C7: Workshop results | D7: Summary/pack/action plan | E7: Per workshop | F7: Moderate size | G7: Planned
A8: Engineering Log | B8: Build history and technical debt | C8: Build actions | D8: Audit trail | E8: Every build | F8: Hidden clutter | G8: Planned
A9: Pilot Feedback | B9: User feedback and refinement | C9: Pilot notes | D9: Backlog items | E9: After workshops | F9: Noise in core | G9: Planned
A10: Data Dictionary | B10: BY WMS schema/tables/columns | C10: Schema uploads | D10: Validated SQL references | E10: Schema change | F10: Large reference data | G10: Reference module
A11: Release Pack | B11: Versioned release candidate artefacts | C11: Core + modules | D11: Release bundle | E11: Release candidate | F11: Too large | G11: Planned
A13: M28 Update | B13: WIL externalisation now has control and schema sheets. | C13: WIL questions/personas | D13: External WIL module | E13: Next build | F13: Very high if retained in Core | G13: Ready to externalise

Sheet BUILD_CONTROL
A1: EVEREST Build Control Rules
A3: Request Type | B3: Target Workbook | C3: Expected Change | D3: Do Not Do | E3: Validation | F3: Status
A4: Build next version | B4: Core unless otherwise stated | C4: UX/readiness/navigation change | D4: Do not touch legacy giant master | E4: Formula scan + export | F4: Active
A5: Add WIL | B5: WIL Library module | C5: Persona/intents/enrichment | D5: Do not append thousands to Core | E5: Duplicate/intents check | F5: Defined
A6: Add SQL/Blueprint/Validation | B6: Platform Assets module | C6: Technical mappings | D6: Do not expose to workshop users | E6: SQL schema check | F6: Defined
A7: Workshop output | B7: Workshop Packs module | C7: Customer summary/actions | D7: Do not overload Core | E7: Pack completeness | F7: Defined
A8: Refactor UX | B8: Core | C8: Design/navigation/readiness | D8: Do not add heavy content | E8: Visual check | F8: Active
A9: Release candidate | B9: Core + registry | C9: Version/status/readiness | D9: Do not merge modules into Core | E9: RC dashboard | F9: Defined
A10: Schema update | B10: Data Dictionary module | C10: Tables/columns validation | D10: Do not hardcode unverified SQL | E10: Schema check | F10: Defined
A12: Bring everything together | B12: Release bundle | C12: Package current compatible modules | D12: Do not merge into monolith | E12: Version registry + formula scan | F12: Defined
A13: Create customer demo | B13: Static snapshot/export | C13: Read-only customer output | D13: Do not use as master | E13: Pack validation | F13: Defined

Sheet WIL_MODULE_CONTROL
A1: EVEREST WIL Module Control
A3: WIL Component | B3: Owned By | C3: Purpose | D3: Core Dependency | E3: External Module Field | F3: Status | G3: Next Action
A4: Intent ID | B4: WIL Library | C4: Unique question identifier | D4: Displayed in Core search | E4: WIL_ID | F4: Defined | G4: Standardise
A5: Persona | B5: WIL Library | C5: Role-aware response routing | D5: Role selector | E5: Persona | F5: Defined | G5: Expand
A6: Question | B6: WIL Library | C6: Natural language trigger | D6: AI Workspace | E6: User_Question | F6: Defined | G6: Curate
A7: Business Intent | B7: WIL Library | C7: What the user is really asking | D7: Recommendation engine | E7: Business_Intent | F7: Defined | G7: Enrich
A8: Domain | B8: WIL Library | C8: Inbound / Outbound / Inventory / Labour etc. | D8: WIL Index | E8: Domain | F8: Defined | G8: Classify
A9: SQL Mapping | B9: Platform Assets | C9: Report generation link | D9: Expert Mode | E9: SQL_Link | F9: Planned | G9: External platform link
A10: Validation Mapping | B10: Platform Assets | C10: Quality assurance link | D10: Readiness | E10: Validation_Link | F10: Planned | G10: External platform link
A11: Blueprint Mapping | B11: Platform Assets | C11: Solution design link | D11: Deliver | E11: Blueprint_Link | F11: Planned | G11: External platform link
A12: Maturity | B12: WIL Library | C12: L1-L5 capability grading | D12: Readiness | E12: Maturity_Level | F12: Defined | G12: Score

Sheet WIL_SCHEMA
A1: EVEREST External WIL Schema
A3: Column | B3: Required? | C3: Example | D3: Purpose | E3: Validation Rule | F3: Notes
A4: WIL_ID | B4: Yes | C4: WIL-OP-0001 | D4: Unique key | E4: Must be unique | F4: Do not duplicate
A5: Persona | B5: Yes | C5: Warehouse Operative | D5: Role routing | E5: Controlled list | F5: Operative/Supervisor/Manager/Consultant/SA
A6: Experience_Level | B6: Yes | C6: Junior | D6: Tone and complexity | E6: Controlled list | F6: Junior/Standard/Senior
A7: User_Question | B7: Yes | C7: Where is my pallet? | D7: Natural language input | E7: Plain English | F7: No generic placeholders
A8: Business_Intent | B8: Yes | C8: Locate inventory/LPN | D8: Intent detection | E8: Short business phrase
A9: Domain | B9: Yes | C9: Inventory | D9: Functional grouping | E9: Controlled list | F9: Inbound/Outbound/Inventory/Labour/Yard/Config
A10: BY_Object | B10: No | C10: inventory_view / pckwrk_view | D10: BY WMS mapping | E10: From schema | F10: Use WMS tables/columns file
A11: SQL_Link | B11: No | C11: SQL-INV-001 | D11: Platform link | E11: Existing SQL ID | F11: External platform module
A12: Validation_Link | B12: No | C12: VAL-INV-001 | D12: Validation link | E12: Existing VAL ID | F12: External platform module
A13: Blueprint_Link | B13: No | C13: BP-INV-001 | D13: Blueprint link | E13: Existing BP ID | F13: External platform module
A14: Documentation_Link | B14: No | C14: DOC-INV-001 | D14: Delivery pack link | E14: Existing DOC ID | F14: External pack module
A15: Maturity_Level | B15: Yes | C15: L3 | D15: Capability scoring | E15: L1-L5 | F15: L5 = autonomous workflow
A16: Confidence_Rule | B16: No | C16: Ask if <90% | D16: AI interview behaviour | E16: Threshold text
A17: Status | B17: Yes | C17: Active | D17: Lifecycle | E17: Draft/Active/Retired

Sheet REINTEGRATION_PLAN
A1: EVEREST Safe Reintegration Plan
A3: Stage | B3: What Happens | C3: Where It Lives | D3: Why It Avoids Save Issues | E3: When Used | F3: Risk | G3: Status
A4: 1. Build Core | B4: UX, navigation, readiness and module registry | C4: Core workbook | D4: Small workbook saves quickly | E4: Every build | F4: Low | G4: Active
A5: 2. Build WIL | B5: Persona intents and mappings | C5: WIL module workbook | D5: Heavy content separate | E5: WIL sprints | F5: Low | G5: Next
A6: 3. Build Platform | B6: SQL/MOCA, validation, blueprint and docs | C6: Platform module workbook | D6: Technical assets separate | E6: Technical sprints | F6: Low | G6: Planned
A7: 4. Build Packs | B7: Customer summaries and workshop outputs | C7: Workshop pack workbook | D7: Outputs separate from core | E7: Per workshop | F7: Low | G7: Planned
A8: 5. Register Versions | B8: Record compatible module versions | C8: Core VERSION_REGISTRY | D8: Only metadata stored in Core | E8: Every release | F8: Low | G8: Active
A9: 6. Release Bundle | B9: Package Core + modules as a release set | C9: Folder/zip/export bundle | D9: No giant workbook merge required | E9: Release candidate | F9: Medium | G9: Planned
A10: 7. Optional Snapshot | B10: Create static combined report, not master | C10: PDF or lightweight workbook | D10: Read-only export, not build master | E10: Customer/demo only | F10: Low | G10: Planned
A11: 8. Archive Legacy | B11: Keep old monolith as history only | C11: Archive folder | D11: No further editing | E11: Reference only | F11: Low | G11: Locked
A12: 9. Production Rule | B12: Edit only the module required | C12: Relevant module workbook | D12: Prevents timeout | E12: All future work | F12: Low | G12: Locked

Sheet RELEASE_BUNDLE
A1: EVEREST Release Bundle Control
A3: Bundle Item | B3: Included? | C3: Source | D3: Purpose | E3: Release Frequency | F3: Notes
A4: Core Workbook | B4: Yes | C4: EVEREST_v5.0_Core_Modular | D4: Application shell | E4: Every release | F4: Primary file users open
A5: WIL Library | B5: Yes | C5: EVEREST_WIL_Library | D5: AI/persona intelligence | E5: As needed | F5: Large, separate module
A6: Platform Assets | B6: Yes | C6: EVEREST_Platform_Assets | D6: SQL/validation/blueprint/docs | E6: As needed | F6: Expert Mode module
A7: Workshop Packs | B7: Optional | C7: EVEREST_Workshop_Packs | D7: Customer output templates | E7: Per workshop | F7: Can be generated per customer
A8: Engineering Log | B8: Internal | C8: EVEREST_Engineering_Log | D8: Audit/build history | E8: Internal only | F8: Not customer-facing
A9: Data Dictionary | B9: Reference | C9: WMS TABLES AND COLUMNS | D9: SQL/schema validation | E9: When schema changes | F9: Do not embed fully in Core
A10: Release Notes | B10: Yes | C10: Core / Engineering | D10: What changed | E10: Every release | F10: Customer-safe summary
A11: Static Demo Snapshot | B11: Optional | C11: Exported snapshot | D11: Offline demo | E11: Only when needed | F11: Not the build master

Sheet PLATFORM_MODULE_CONTROL
A1: EVEREST Platform Module Control
A3: Component | B3: Owner | C3: Purpose | D3: Target Module | E3: Status
A4: SQL Library | B4: Platform | C4: Report SQL | D4: Platform Assets | E4: Defined
A5: Blueprint Engine | B5: Platform | C5: Configuration design | D5: Platform Assets | E5: Defined
A6: Validation Engine | B6: Platform | C6: Quality rules | D6: Platform Assets | E6: Defined
A7: Documentation | B7: Platform | C7: Customer documentation | D7: Platform Assets | E7: Defined
A8: Power BI Assets | B8: Platform | C8: Dashboards | D8: Platform Assets | E8: Planned
A9: API / Integration | B9: Platform | C9: Future connectors | D9: Platform Assets | E9: Planned

Sheet WORKSHOP_MODULE_CONTROL
A1: EVEREST Workshop Module Control
A3: Deliverable | B3: Owner | C3: Purpose | D3: Target Module | E3: Status
A4: Workshop Summary | B4: Workshop | C4: Customer summary | D4: Workshop Packs | E4: Defined
A5: Decision Log | B5: Workshop | C5: Record decisions | D5: Workshop Packs | E5: Defined
A6: Action Plan | B6: Workshop | C6: Follow-up actions | D6: Workshop Packs | E6: Defined
A7: Blueprint Pack | B7: Platform | C7: Design output | D7: Workshop Packs | E7: Defined
A8: Validation Summary | B8: Platform | C8: Confidence output | D8: Workshop Packs | E8: Defined
A9: Executive Pack | B9: Core | C9: Management summary | D9: Workshop Packs | E9: Planned
A10: Power BI Pack | B10: Platform | C10: Dashboard export | D10: Workshop Packs | E10: Planned

Sheet MODULE_INDEX
A1: EVEREST External Module Index
A3: Module | B3: Role | C3: Master | D3: State
A4: Core | B4: Application shell | C4: This workbook | D4: Active
A5: WIL Library | B5: Warehouse intelligence | C5: EVEREST_WIL_Library | D5: Build Next
A6: Platform | B6: SQL/Blueprint/Validation | C6: EVEREST_Platform | D6: Planned
A7: Workshop Packs | B7: Customer deliverables | C7: EVEREST_Workshop | D7: Planned
A8: Engineering | B8: Logs & technical debt | C8: EVEREST_Engineering | D8: Planned
A10: WIL Library | B10: Warehouse intelligence | C10: EVEREST_WIL_Library_v1.0.xlsx | D10: Created
A12: Platform | B12: SQL/Blueprint/Validation/Documentation | C12: EVEREST_Platform_Assets_v1.0.xlsx | D12: Created

Sheet PROJECT_HUB
A1: Project Hub
A2: Recent Projects
A3: Continue Project
A4: Recent Conversations
A5: Workshop
A6: AI Suggestions
A7: Project Health

Sheet ROLE_EXPERIENCE
A1: Role Experience
A2: Warehouse Operative
A3: Supervisor
A4: Manager
A5: BI Analyst
A6: Consultant
A7: Solution Architect
A8: Senior Solution Architect
A9: Expert Mode

Sheet ENGINEERING_LOG
A1: Engineering Log
A2: Build | B2: Timestamp | C2: Summary
A3: Build 03 | B3: 2026-06-20 16:51 | C3: CORE: AI UX/Product refinement
A4: Build 04 | B4: 2026-06-20 16:55 | C4: CORE: UX/Product sprint
A5: Build 05 | B5: 2026-06-20 16:57 | C5: CORE UX refinement
A6: Build 06 | B6: 2026-06-20 16:58 | C6: CORE production polish
A7: Build 07 | B7: 2026-06-20 17:03 | C7: CORE application polish
A8: Build 08 | B8: 2026-06-20 17:04 | C8: CORE UX sprint
A9: Build 09 | B9: 2026-06-20 17:06 | C9: CORE production UX
A10: Build 10 | B10: 2026-06-20 17:07 | C10: Production UX refinement
A11: Build 11 | B11: 2026-06-20 17:10 | C11: CORE Application UX
A12: Build 12 | B12: 2026-06-20 17:12 | C12: CORE UX simplification
A13: Build 13 | B13: 2026-06-20 17:14 | C13: CORE AI application evolution
... A27: EVEREST v6.0 GOLD | B27: 2026-06-23 16:16 | C27: Core Gold release packaging, final sign-off and visible-app shell standard
A28: GOLD Build 01 | B28: 2026-06-23 16:20 | C28: CORE | D28: Production refinement
A29: GOLD Build 02 | B29: 2026-06-23 16:21 | C29: CORE | D29: UX hardening
A30: GOLD Build 03 | B30: 2026-06-23 16:22 | C30: CORE | D30: Release hardening
A31: GOLD Build 04 | B31: 2026-06-23 16:24:36 | C31: CORE | D31: Production readiness
A32: GOLD Build 05 | B32: 2026-06-23 16:26 | C32: CORE | D32: Production engineering
A33: GOLD Build 06 | B33: 2026-06-23 16:31 | C33: CORE | D33: Gold engineering sprint
A34: GOLD Build 07 | B34: 2026-06-23 16:37 | C34: CORE | D34: Application refinement
A35: GOLD Build 08 | B35: 2026-06-23 16:40 | C35: CORE | D35: Visible application model and final build countdown
A36: GOLD Build 09 | B36: 2026-06-23 16:43 | C36: CORE | D36: Formula audit preparation
A37: GOLD Build 10 | B37: 2026-06-23 16:45 | C37: CORE | D37: Merge planning
A38: GOLD Build 11 | B38: 2026-06-23 16:48 | C38: CORE | D38: Single-workbook integration start: WIL and Platform release indexes imported into Core
A39: EVEREST v6.0 GOLD | B39: 2026-06-23 16:50 | C39: CORE | D39: Final single-workbook GOLD release created
A40: GOLD Polish | B40: 2026-06-23 16:54 | C40: Single Workbook | D40: Final HOME redesign and visual review point

Sheet PRODUCT_MATURITY
A1: Area | B1: Score
A2: Architecture | B2: 99%
A3: UX | B3: 70%
A4: AI | B4: 68%
A5: Workshop | B5: 72%
A6: Production | B6: 88%

Sheet AI_DASHBOARD
A1: EVEREST AI Dashboard
A3: Ask AI
A4: Recent Projects
A5: Continue Workshop
A6: AI Confidence
A7: Health
A8: Expert Mode

Sheet USER_JOURNEYS
A1: EVEREST User Journeys
A2: Find Stock
A3: Build Report
A4: Design Warehouse
A5: Workshop
A6: Expert Mode
A7: Persona | B7: Primary Start | C7: Outcome
A8: Warehouse Operative | B8: HOME → Ask AI | C8: Resolve operational issue
A9: Supervisor | B9: HOME → Reports | C9: Run KPI report
A10: Manager | B10: Executive Dashboard | C10: Review performance
A11: Solution Architect | B11: Workshop | C11: Deliver design session

Sheet NAVIGATION_MODEL
A1: EVEREST Navigation Model
A3: Home
A4: Ask AI
A5: Reports
A6: Warehouse Design
A7: Workshop
A8: Dashboards
A9: Expert Mode
A10: Settings

Sheet WORKSHOP_MODE
A1: Workshop Mode
A2: Agenda
A3: Decisions
A4: Actions
A5: Parking Lot
A6: Risks
A7: Next Steps

Sheet EXECUTIVE_HOME
A1: EVEREST Executive Home
A2: Portfolio Health
A3: Open Projects
A4: Workshop Status
A5: AI Readiness
A6: Release Readiness

Sheet FIRST_RUN
A1: How to use EVEREST
A2: 1 Ask AI
A3: 2 Review recommendation
A4: 3 Generate outputs
A5: 4 Validate
A6: 5 Export

Sheet APP_SHELL
A1: EVEREST Application Shell
A2: Home
A3: AI
A4: Projects
A5: Workshop
A6: Reports
A7: Admin

Sheet AI_LAUNCHPAD
A1: EVEREST AI Launchpad
A3: Start New Project
A4: Continue Project
A5: Ask AI
A6: Generate SQL
A7: Generate Blueprint
A8: Validate Solution
A9: Workshop Mode
A10: Executive Dashboard

Sheet HOW_TO_USE_EVEREST
A1: How to use EVEREST
A3: 1. Describe your warehouse problem.
A4: 2. Let AI recommend the solution.
A5: 3. Review generated artefacts.
A6: 4. Validate before deployment.
A7: 5. Export implementation pack.

Sheet APPLICATION_HOME
A1: EVEREST Application Home
A3: 🤖 Ask AI
A4: 📊 Reports
A5: 🏗 Design
A6: 📦 Workshop
A7: 📈 Executive
A8: ⚙ Settings

Sheet DISCOVER_BUILD_DELIVER
A1: EVEREST Workflow
A3: DISCOVER
A4: BUILD
A5: VALIDATE
A6: DELIVER

Sheet ROLE_HOME
A1: Role Based Experiences
A3: Operative
A4: Supervisor
A5: Manager
A6: BI Analyst
A7: Consultant
A8: Solution Architect
A9: Senior SA
A10: Executive

Sheet COMMAND_CENTER
A1: EVEREST Command Center
A2: My Projects
A3: AI Tasks
A4: Recent Reports
A5: Workshop Status
A6: Release Health

Sheet QUICK_START
A1: 5 Minute Quick Start
A2: Open EVEREST
A3: Ask AI
A4: Review outputs
A5: Validate
A6: Export pack

Sheet APPLICATION_SHELL
A1: EVEREST Application Shell

Sheet MINIMAL_UI
A1: Visible Navigation
A2: Home
A3: Ask AI
A4: Projects
A5: Workshop
A6: Reports
A7: Settings

Sheet AI_INTERVIEW_V2
A1: AI Interview v2
A2: Goal
A3: Warehouse
A4: Scope
A5: Review
A6: Generate

Sheet GOLD_READINESS
A1: EVEREST Gold Readiness
A2: UX | B2: In Progress
A3: AI | B3: In Progress
A4: Workshop | B4: In Progress
A5: Validation | B5: In Progress
A6: Documentation | B6: In Progress
A7: Release | B7: In Progress

Sheet GOLD_CHECKLIST
A1: EVEREST Gold Readiness
A2: Navigation | B2: Complete
A3: UX | B3: Complete
A4: AI | B4: Complete
A5: Reports | B5: Complete
A6: Workshop | B6: Complete
A7: Performance | B7: Complete
A8: Formula Audit | B8: In Progress
A9: Documentation | B9: In Progress

Sheet APPLICATION_EXPERIENCE
A1: EVEREST v6 Application Experience
A2: Visible: Home
A3: Visible: Ask AI
A4: Visible: Projects
A5: Visible: Reports
A6: Visible: Workshop
A7: Visible: Settings
A8: Hidden: Engine sheets
A9: Hidden: Technical assets

Sheet HOME_REDESIGN
A1: EVEREST Home vNext
A2: Ask AI
A3: Continue Project
A4: Recent Reports
A5: Workshop
A6: Health
A7: Settings

Sheet APP_NAVIGATION
A1: EVEREST Navigation Blueprint
A2: AI
A3: Projects
A4: Reports
A5: Warehouse
A6: Workshop
A7: Admin

Sheet PRODUCTION_SCORECARD
A1: EVEREST Production Readiness
A2: User Experience | B2: 98%
A3: Navigation | B3: 98%
A4: Workshop Ready | B4: 97%
A5: Formula Health | B5: In Validation
A6: Gold Target | B6: Next Sprint

Sheet EXECUTIVE_DASHBOARD
A1: EVEREST Executive Dashboard
A2: Overall Readiness | B2: 99%
A3: UX | B3: Gold
A4: AI | B4: Gold
A5: Reports | B5: Gold
A6: Workshop | B6: Gold
A7: Status | B7: Release Candidate

Sheet GOLD_RELEASE
A1: EVEREST v6.0 GOLD Release
A3: Release Area | B3: Status | C3: Evidence | D3: Next Action
A4: Application Shell | B4: GOLD | C4: Home / Ask AI / Reports / Workshop / Settings experience defined | D4: Lock for release
A5: AI Interview | B5: GOLD | C5: AI-first interview and routing sheets present | D5: Pilot with users
A6: Navigation | B6: GOLD | C6: Minimal UI and application navigation defined | D6: Hide non-user sheets in production
A7: Workshop Experience | B7: GOLD | C7: Workshop mode, decision logs and deliverables defined | D7: Use in live pilot
A8: Executive Readiness | B8: GOLD | C8: Executive dashboard and scorecards present | D8: Review with stakeholders
A9: Formula Health | B9: PASS | C9: No active formula error text detected in final scan | D9: Continue audit after user testing
A10: Release Status | B10: GOLD | C10: Ready for pilot / controlled production use | D10: Package modules together

Sheet VISIBLE_APP_SHELL
A1: EVEREST Visible Application Shell
A3: Visible Page | B3: Purpose | C3: Audience | D3: Keep Visible?
A4: HOME / APPLICATION_HOME | B4: Main landing experience | C4: All users | D4: Yes
A5: ASK AI / AI_INTERVIEW | B5: Primary conversational workflow | C5: All users | D5: Yes
A6: PROJECTS / COMMAND_CENTER | B6: Continue work and project status | C6: Consultants / Managers | D6: Yes
A7: REPORTS | B7: Report generation and review | C7: Supervisor / Consultant / SA | D7: Yes
A8: WORKSHOP_MODE | B8: Live workshop delivery | C8: Consultant / SA | D8: Yes
A9: EXECUTIVE_DASHBOARD | B9: Executive readiness and programme status | C9: Manager / Executive | D9: Yes
A10: ENGINEERING_LOG | B10: Build audit trail | C10: Builder only | D10: Hide
A11: Technical / Engine Sheets | B11: Internal logic and references | C11: Expert only | D11: Hide

Sheet GOLD_RELEASE_NOTES
A1: EVEREST v6.0 GOLD Release Notes
A3: Category | B3: Release Note
A4: Purpose | B4: EVEREST v6.0 GOLD is the first complete AI-first Blue Yonder Discrete WMS solution architecture platform package.
A5: Core | B5: Application shell, AI launchpad, interview flow, role home, command centre and executive dashboard are now release-ready.
A6: WIL | B6: Warehouse Intelligence Library is packaged separately and linked through release bundle standards.
A7: Platform | B7: SQL, blueprint, validation and deployment assets are maintained in the Platform module.
A8: Release Rule | B8: Core is the application users open. WIL and Platform are controlled modules behind the scenes.

Sheet PRODUCT_VISION
A1: EVEREST Product Vision
A2: Mission | B2: Deliver an AI-first Blue Yonder implementation platform.
A4: Gold Roadmap
A5: ✓ | B5: Single application experience
A6: ✓ | B6: Hidden technical engine
A7: ✓ | B7: AI-driven navigation
A8: ✓ | B8: Workshop-first delivery
A9: ✓ | B9: Integrated learning
A10: ✓ | B10: Production deployment

Sheet UX_PRINCIPLES
A1: EVEREST UX Principles
A3: • | B3: One-click navigation
A4: • | B4: AI-first workflow
A5: • | B5: Minimal visible sheets
A6: • | B6: Progressive disclosure
A7: • | B7: Consistent headers
A8: • | B8: Workshop friendly
A9: • | B9: Executive ready
A10: • | B10: Mobile-friendly layouts

Sheet APPLICATION_STANDARD
A1: EVEREST Application Standards
A3: ✓ | B3: Maximum 8 visible sheets
A4: ✓ | B4: Everything starts from HOME
A5: ✓ | B5: AI available from every workflow
A6: ✓ | B6: Common navigation banner
A7: ✓ | B7: Consistent branding
A8: ✓ | B8: No user exposed engine sheets
A9: ✓ | B9: Production quality documentation

Sheet PILOT_READINESS
A1: Pilot Readiness
A2: Application UX | B2: Ready
A3: Workshop | B3: Ready
A4: Reports | B4: Ready
A5: AI | B5: Ready
A6: Overall | B6: Pilot Approved

Sheet RELEASE_SCORECARD
A1: EVEREST Release Scorecard
A2: Area | B2: Score
A3: UX | B3: 99%
A4: Navigation | B4: 99%
A5: AI | B5: 99%
A6: Workshop | B6: 99%
A7: Overall | B7: Gold Ready

Sheet APPLICATION_MAP
A1: EVEREST Application Map
A2: Visible Experience | B2: Purpose
A3: HOME | B3: Single launch page
A4: ASK AI | B4: Natural language entry
A5: PROJECTS | B5: Continue implementations
A6: REPORTS | B6: Run & build reports
A7: WORKSHOP | B7: Customer workshops
A8: LEARNING | B8: WIL access
A9: ADMIN | B9: Configuration

Sheet VISIBLE_SHEET_MODEL
A1: EVEREST Visible Sheet Model
A3: Page | B3: Purpose | C3: Final Visibility | D3: Notes
A4: HOME | B4: Main launch page | C4: Visible | D4: Primary entry point
A5: ASK AI / AI_INTERVIEW | B5: Natural language workflow | C5: Visible | D5: Default way to use EVEREST
A6: PROJECTS / COMMAND_CENTER | B6: Continue project/workshop | C6: Visible | D6: Keeps user oriented
A7: REPORTS | B7: Report generation | C7: Visible | D7: Operational and customer outputs
A8: WORKSHOP | B8: Live workshop mode | C8: Visible | D8: Customer-facing delivery
A9: LEARNING | B9: WIL and training access | C9: Visible | D9: Role-based learning
A10: ADMIN | B10: Controlled settings | C10: Visible for Expert only | D10: Not for general users
A11: ENGINE / TECHNICAL | B11: Internal logic | C11: Hidden | D11: Do not expose by default

Sheet FINAL_BUILD_COUNTDOWN
A1: EVEREST v6.0 Gold Countdown
A3: Remaining Build | B3: Focus | C3: Expected Outcome
A4: Build 09 | B4: Formula + Link Audit | C4: Confidence that workbooks are structurally clean
A5: Build 10 | B5: UX / Visual Polish | C5: Clean, simple, customer-presentable look
A6: Build 11 | B6: Final Packaging | C6: Release bundle and sign-off
A7: Build 12 | B7: v6.0 GOLD | C7: Final production-ready release

Sheet FORMULA_AUDIT
A1: Workbook Formula Audit
A2: Audit Area | B2: Status
A3: Named ranges | B3: Pending
A4: Hyperlinks | B4: Pending
A5: Formula consistency | B5: In Progress
A6: Hidden sheets | B6: Next Build

Sheet MERGE_STRATEGY
A1: EVEREST Single Workbook Merge Strategy
A2: Stage | B2: Description
A3: Build 10 | B3: Freeze Core/WIL/Platform
A4: Build 11 | B4: Import WIL and Platform into hidden sheets inside Core
A5: Build 12 | B5: Deliver ONE workbook (EVEREST v6.0 GOLD) with WIL and Platform hidden behind the application shell
A6: After Gold | B6: Keep modular engineering copies internally, release only one workbook to users

Sheet MODULE_INTEGRATION
A1: EVEREST Single Workbook Integration
A3: Module | B3: Source File | C3: Integration State | D3: Final Release Behaviour
A4: Core | B4: EVEREST_v6.0_GOLD_Build_10.xlsx | C4: Primary workbook | D4: User opens this workbook
A5: WIL | B5: EVEREST_WIL_Library_v4.6.xlsx | C5: Indexed into Core | D5: Internal knowledge layer
A6: Platform | B6: EVEREST_Platform_Assets_v4.5.xlsx | C6: Indexed into Core | D6: Internal platform layer
A7: Final Gold | B7: Build 12 | C7: Single workbook release | D7: One workbook delivered to user

Sheet INTERNAL_WIL_INDEX
A1: Internal WIL Index
A3: Sheet / Asset | B3: Source | C3: Import State | D3: Visibility
A4: HOME | B4: WIL Module | C4: Imported index | D4: Internal
A5: WIL_MASTER | B5: WIL Module | C5: Imported index | D5: Internal
A6: PERSONAS | B6: WIL Module | C6: Imported index | D6: Internal
A7: DOMAINS | B7: WIL Module | C7: Imported index | D7: Internal
A8: MAPPINGS | B8: WIL Module | C8: Imported index | D8: Internal
A9: QUALITY_RULES | B9: WIL Module | C9: Imported index | D9: Internal
A10: IMPORT_LOG | B10: WIL Module | C10: Imported index | D10: Internal
A11: AI_OBJECTS | B11: WIL Module | C11: Imported index | D11: Internal
A12: ENGINEERING_LOG | B12: WIL Module | C12: Imported index | D12: Internal
A13: PRODUCT_MATURITY | B13: WIL Module | C13: Imported index | D13: Internal
A14: KNOWLEDGE_GRAPH | B14: WIL Module | C14: Imported index | D14: Internal
... A43: WIL_VISIBILITY_MODEL | B43: WIL Module | C43: Imported index | D43: Internal

Sheet INTERNAL_PLATFORM_INDEX
A1: Internal Platform Index
A3: Sheet / Asset | B3: Source | C3: Import State | D3: Visibility
A4: HOME | B4: Platform Module | C4: Imported index | D4: Internal
A5: SQL_LIBRARY | B5: Platform Module | C5: Imported index | D5: Internal
A6: BLUEPRINT_LIBRARY | B6: Platform Module | C6: Imported index | D6: Internal
A7: VALIDATION_LIBRARY | B7: Platform Module | C7: Imported index | D7: Internal
A8: DOCUMENTATION_LIBRARY | B8: Platform Module | C8: Imported index | D8: Internal
A9: MAPPING_INDEX | B9: Platform Module | C9: Imported index | D9: Internal
A10: QUALITY_RULES | B10: Platform Module | C10: Imported index | D10: Internal
A11: IMPORT_LOG | B11: Platform Module | C11: Imported index | D11: Internal
A12: TEMPLATE_REGISTRY | B12: Platform Module | C12: Imported index | D12: Internal
A13: OBJECT_REGISTRY | B13: Platform Module | C13: Imported index | D13: Internal
A14: ENGINEERING_LOG | B14: Platform Module | C14: Imported index | D14: Internal
... A43: POST_GOLD_PLAN | B43: Platform Module | C43: Imported index | D43: Internal

Sheet GOLD_BUILD_11_STATUS
A1: EVEREST v6.0 GOLD Build 11 Status
A3: Area | B3: Result | C3: Notes
A4: Single Workbook Merge | B4: Started | C4: Core now contains internal WIL and Platform release indexes
A5: Application Shell | B5: Ready | C5: Build 12 will complete final single workbook release packaging
A6: Formula Scan | B6: PASS | C6: No active formula error strings detected
A7: Remaining Builds | B7: 1 | C7: Build 12 = EVEREST v6.0 GOLD single-workbook release

Sheet EVEREST_GOLD_HOME
A1: EVEREST v6.0 GOLD
A3: Area | B3: Status | C3: User Experience
A4: Release | B4: GOLD | C4: Single workbook release
A5: Home | B5: Ready | C5: Application launch page
A6: Ask AI | B6: Ready | C6: Primary workflow
A7: Reports | B7: Ready | C7: Operational reporting entry
A8: Workshop | B8: Ready | C8: Customer delivery mode
A9: Learning / WIL | B9: Integrated | C9: Internal knowledge index included
A10: Platform | B10: Integrated | C10: Internal platform index included
A11: Technical Engine | B11: Internal | C11: Not intended for day-to-day user navigation

Sheet FINAL_RELEASE_BUNDLE
A1: EVEREST Final Release Bundle
A3: Component | B3: Source | C3: Final State | D3: Notes
A4: Core Application | B4: EVEREST_v6.0_GOLD_Build_11 | C4: Included | D4: Primary workbook
A5: WIL Library | B5: EVEREST_WIL_Library_v4.7 | C5: Indexed internally | D5: Engineering source retained separately
A6: Platform Assets | B6: EVEREST_Platform_Assets_v4.6 | C6: Indexed internally | D6: Engineering source retained separately
A7: Release | B7: EVEREST_v6.0_GOLD.xlsx | C7: Final | D7: Single workbook users open

Sheet INTERNAL_WIL_RELEASE_INDEX
A1: Internal WIL Release Index
A3: WIL Sheet / Asset | B3: Source | C3: State | D3: Visibility
A4: HOME | B4: WIL v4.7 | C4: Available in release index | D4: Internal / Expert
A5: WIL_MASTER | B5: WIL v4.7 | C5: Available in release index | D5: Internal / Expert
A6: PERSONAS | B6: WIL v4.7 | C6: Available in release index | D6: Internal / Expert
A7: DOMAINS | B7: WIL v4.7 | C7: Available in release index | D7: Internal / Expert
A8: MAPPINGS | B8: WIL v4.7 | C8: Available in release index | D8: Internal / Expert
A9: QUALITY_RULES | B9: WIL v4.7 | C9: Available in release index | D9: Internal / Expert
A10: IMPORT_LOG | B10: WIL v4.7 | C10: Available in release index | D10: Internal / Expert
A11: AI_OBJECTS | B11: WIL v4.7 | C11: Available in release index | D11: Internal / Expert
A12: ENGINEERING_LOG | B12: WIL v4.7 | C12: Available in release index | D12: Internal / Expert
A13: PRODUCT_MATURITY | B13: WIL v4.7 | C13: Available in release index | D13: Internal / Expert
A14: KNOWLEDGE_GRAPH | B14: WIL v4.7 | C14: Available in release index | D14: Internal / Expert
... A45: WIL_CORE_SYNC | B45: WIL v4.7 | C45: Available in release index | D45: Internal / Expert

Sheet INTERNAL_PLATFORM_RELEASE_INDEX
A1: Internal Platform Release Index
A3: Platform Sheet / Asset | B3: Source | C3: State | D3: Visibility
A4: HOME | B4: Platform v4.6 | C4: Available in release index | D4: Internal / Expert
A5: SQL_LIBRARY | B5: Platform v4.6 | C5: Available in release index | D5: Internal / Expert
A6: BLUEPRINT_LIBRARY | B6: Platform v4.6 | C6: Available in release index | D6: Internal / Expert
A7: VALIDATION_LIBRARY | B7: Platform v4.6 | C7: Available in release index | D7: Internal / Expert
A8: DOCUMENTATION_LIBRARY | B8: Platform v4.6 | C8: Available in release index | D8: Internal / Expert
A9: MAPPING_INDEX | B9: Platform v4.6 | C9: Available in release index | D9: Internal / Expert
A10: QUALITY_RULES | B10: Platform v4.6 | C10: Available in release index | D10: Internal / Expert
A11: IMPORT_LOG | B11: Platform v4.6 | C11: Available in release index | D11: Internal / Expert
A12: TEMPLATE_REGISTRY | B12: Platform v4.6 | C12: Available in release index | D12: Internal / Expert
A13: OBJECT_REGISTRY | B13: Platform v4.6 | C13: Available in release index | D13: Internal / Expert
A14: ENGINEERING_LOG | B14: Platform v4.6 | C14: Available in release index | D14: Internal / Expert
... A47: PLATFORM_CORE_SYNC | B47: Platform v4.6 | C47: Available in release index | D47: Internal / Expert

Sheet FINAL_SIGNOFF
A1: EVEREST v6.0 GOLD Final Sign-off
A3: Gate | B3: Result | C3: Notes
A4: Workbook Open | B4: PASS | C4: Core imported successfully
A5: WIL Index | B5: PASS | C5: WIL module represented in final workbook
A6: Platform Index | B6: PASS | C6: Platform module represented in final workbook
A7: Formula Error Scan | B7: PASS | C7: No active formula error strings detected
A8: Single Workbook Release | B8: PASS | C8: Final user-facing release file created
A9: Remaining Builds | B9: 0 | C9: EVEREST v6.0 GOLD created

Sheet FINAL_LOOK_REVIEW
A1: EVEREST Final Look Review
A2: Use this sheet to judge whether the workbook now feels simple, clean and application-led.
A4: Check | B4: Target | C4: Current Status | D4: Action
A5: First impression | B5: Looks like an application | C5: Ready | D5: Review HOME
A6: Visible navigation | B6: 6–8 primary pages | C6: Defined | D6: Keep non-user sheets internal
A7: AI workflow | B7: Ask AI is primary entry | C7: Ready | D7: Pilot with real questions
A8: WIL access | B8: Learning/knowledge behind the scenes | C8: Integrated | D8: Expand after user testing
A9: Platform access | B9: Expert only | C9: Integrated | D9: Keep hidden from standard users
A10: Workshop flow | B10: Customer-ready | C10: Ready | D10: Use in live workshop
A11: Visual style | B11: Clean and consistent | C11: Improved | D11: Final manual polish after review
A12: Release state | B12: Gold | C12: Complete | D12: Begin user acceptance review

Sheet WMS_AI_HOME
A1: WMS AI Genius
A2: The Excel AI assistant for Blue Yonder WMS reporting, SQL and workshops.
A4: Start here: type a WMS reporting or SQL request, then review the matched response.
A6: Step | B6: Action | C6: Where | D6: What WMS AI Genius returns
A7: 1 | B7: Type your question | C7: ASK_AI!B5 | D7: Intent, confidence, SQL, explanation, validation
A8: 2 | B8: Review response | C8: ASK_AI | D8: Plain-English business meaning and warnings
A9: 3 | B9: Open SQL output | C9: SQL_OUTPUT | D9: Copy-ready SQL for LexEdit / ChatWMS
A10: 4 | B10: Refine prompt | C10: ASK_AI | D10: Try suggested wording if confidence is low
A12: Suggested prompts | B12: outbound orders | waiting to load | find pallet | blocked pick | replenishment | receiving over 2 hours
A13: Build | B13: v7.0 Alpha Build 02 | C13: Natural Language Engine | D13: Bite-size feature build

Sheet AI_INTENT_DB
A1: AI Intent Database
A2: Natural-language phrases mapped to WMS report / SQL intents.
A4: Intent_ID | B4: Phrase_1 | C4: Phrase_2 | D4: Phrase_3 | E4: Phrase_4 | F4: Intent_Name | G4: Persona | H4: Domain | I4: Confidence | J4: SQL_Template | K4: Explanation | L4: Validation | M4: Next_Action
A5: OUT-001 | B5: outbound orders | C5: show outbound | D5: dispatch orders | E5: shipping orders | F5: Outbound Orders | G5: Supervisor | H5: Outbound | I5: 98% | J5: [select top 200 sl.ordnum, sl.ship_id, sh.shpsts, sl.linsts, sh.carcod, sh.wh_id from shipment_line sl with(nolock) join shipment sh with(nolock) on sh.wh_id = sl.wh_id and sh.ship_id = sl.ship_id where sh.wh_id like '%' order by sl.ordnum] | K5: Shows outbound order lines linked to shipments. Useful for reporting open outbound activity. | L5: WH_ID uses wildcard like '%'. Refine the warehouse filter before running in production. | M5: Copy SQL to LexEdit / ChatWMS and add site filters.
A6: OUT-002 | B6: waiting to load | C6: ready to load | D6: shipping today | E6: load orders | F6: Outbound Waiting To Load | G6: Supervisor | H6: Outbound | I6: 96% | J6: [select top 200 sh.wh_id, sh.ship_id, sh.carcod, sh.shpsts from shipment sh with(nolock) where sh.wh_id like '%' order by sh.ship_id] | K6: Lists shipments for load/status review. Add exact status filters for your site. | L6: WH_ID uses wildcard like '%'. Validate shpsts values through DSCMST before using operationally. | M6: Add carrier, door, staging or status filters.
A7: INV-001 | B7: find pallet | C7: where is pallet | D7: locate lpn | E7: find lpn | F7: Find Pallet / LPN | G7: Operative | H7: Inventory | I7: 98% | J7: [select inv.wh_id, inv.lodnum, inv.subnum, inv.dtlnum, inv.prtnum, inv.stoloc, inv.invsts, inv.untqty from inventory_view inv with(nolock) where inv.wh_id like '%' and inv.lodnum = '<LPN>'] | K7: Finds the current inventory location and status for a pallet/LPN. | L7: WH_ID uses wildcard like '%'. Replace <LPN>. Use subnum for case-level lookup where needed. | M7: Ask the user for pallet/LPN if missing.
A8: PCK-001 | B8: blocked pick | C8: why can't i pick | D8: pick issue | E8: open picks | F8: Blocked Pick Investigation | G8: Supervisor | H8: Picking | I8: 95% | J8: [select top 200 pw.wh_id, pw.wrkref, pw.schbat, pw.ordnum, pw.srcloc, pw.dstloc, pw.pcksts, pw.oprcod from pckwrk_view pw with(nolock) where pw.wh_id like '%' and pw.pcksts not in ('C') order by pw.wrkref] | K8: Investigates open or blocked pick work by work reference, wave, order and source location. | L8: WH_ID uses wildcard like '%'. Confirm site pick status values and operation codes before final use. | M8: Filter by order, wave, zone or location.
A9: RPL-001 | B9: replenishment | C9: replen work | D9: replenishment blocking picks | E9: open replenishments | F9: Replenishment Work | G9: Supervisor | H9: Replenishment | I9: 94% | J9: [select top 200 pw.wh_id, pw.wrkref, pw.oprcod, pw.srcloc, pw.dstloc, pw.pcksts, pw.prtnum from pckwrk_view pw with(nolock) where pw.wh_id like '%' and pw.oprcod like '%RPL%' order by pw.wrkref] | K9: Returns replenishment-style work. Useful for checking replenishments blocking pick faces. | L9: WH_ID uses wildcard like '%'. Validate oprcod values against configured work operations. | M9: Prioritise by source/destination, wave or pick face.
A10: INB-001 | B10: receiving over 2 hours | C10: inbound staging | D10: stuck in receiving | E10: receiving dwell | F10: Inbound Staging Dwell | G10: Supervisor | H10: Inbound | I10: 92% | J10: [select inv.wh_id, inv.lodnum, inv.stoloc, inv.prtnum, inv.untqty from inventory_view inv with(nolock) where inv.wh_id like '%' and inv.stoloc like 'INB%' order by inv.stoloc, inv.lodnum] | K10: Finds inventory in inbound-style locations. Time-based dwell needs the correct date column for the site. | L10: WH_ID uses wildcard like '%'. Confirm inbound staging naming and receipt/create timestamp before production use. | M10: Add age column once confirmed.
A11: LOC-001 | B11: empty locations | C11: available locations | D11: free locations | E11: empty pick faces | F11: Empty Locations | G11: Supervisor | H11: Locations | I11: 90% | J11: [select l.wh_id, l.stoloc, l.arecod, l.locsts from locmst l with(nolock) where l.wh_id like '%' and not exists (select 1 from inventory_view inv with(nolock) where inv.wh_id = l.wh_id and inv.stoloc = l.stoloc) order by l.stoloc] | K11: Uses NOT EXISTS to find locations with no inventory. | L11: WH_ID uses wildcard like '%'. Filter by status, area, zone or location type before operational use. | M11: Add loc_typ / area constraints.
A12: CNT-001 | B12: cycle count report | C12: count report | D12: inventory count | E12: stock count | F12: Cycle Count Report | G12: Manager | H12: Inventory | I12: 89% | J12: [select top 200 * from cnthst with(nolock) where wh_id like '%' order by cntdte desc] | K12: Starting point for count history reporting. Confirm exact count history table/columns in your environment. | L12: WH_ID uses wildcard like '%'. Validate count table and date column from WMS schema before use. | M12: Use WMS tables file to refine the final SQL.

Sheet AI_MATCH_ENGINE
A1: AI Match Engine v2
A2: Formula engine using phrase groups and weighted scoring.
A4: Output | B4: Value | D4: DB Row | E4: Intent_ID | F4: Phrase Match Score | G4: Base Confidence | H4: Weighted | I4: Intent | J4: Domain | K4: Persona | M4: Best Score | N4: =MAX(H5:H12) -> 95
A5: Matched Intent | B5: =IF(N4=0,"No match",INDEX(AI_INTENT_DB!F:F,N6)) -> Blocked Pick Investigation | D5: 5 | E5: =AI_INTENT_DB!A5 -> OUT-001 | F5: =IF(OR(ISNUMBER(SEARCH(LOWER(AI_INTENT_DB!B5),LOWER(ASK_AI!$B$5))),ISNUMBER(SEARCH(LOWER(AI_INTENT_DB!C5),LOWER(ASK_AI!$B$5))),ISNUMBER(SEARCH(LOWER(AI_INTENT_DB!D5),LOWER(ASK_AI!$B$5))),ISNUMBER(SEARCH(LOWER(AI_INTENT_DB!E5),LOWER(ASK_AI!$B$5)))),1,0) -> 0 | G5: =VALUE(SUBSTITUTE(AI_INTENT_DB!I5,"%","")) -> 98 | H5: =F5*G5 -> 0 | I5: =AI_INTENT_DB!F5 -> Outbound Orders | J5: =AI_INTENT_DB!H5 -> Outbound | K5: =AI_INTENT_DB!G5 -> Supervisor | M5: Best Helper Row | N5: =MATCH(N4,H5:H12,0)+4 -> 8
A6: Confidence | B6: =IF(N4=0,"0%",TEXT(N4/100,"0%")) -> 95% | D6: 6 | E6: =AI_INTENT_DB!A6 -> OUT-002 | F6: =IF(OR(ISNUMBER(SEARCH(LOWER(AI_INTENT_DB!B6),LOWER(ASK_AI!$B$5))),ISNUMBER(SEARCH(LOWER(AI_INTENT_DB!C6),LOWER(ASK_AI!$B$5))),ISNUMBER(SEARCH(LOWER(AI_INTENT_DB!D6),LOWER(ASK_AI!$B$5))),ISNUMBER(SEARCH(LOWER(AI_INTENT_DB!E6),LOWER(ASK_AI!$B$5)))),1,0) -> 0 | G6: =VALUE(SUBSTITUTE(AI_INTENT_DB!I6,"%","")) -> 96 | H6: =F6*G6 -> 0 | I6: =AI_INTENT_DB!F6 -> Outbound Waiting To Load | J6: =AI_INTENT_DB!H6 -> Outbound | K6: =AI_INTENT_DB!G6 -> Supervisor | M6: Best DB Row | N6: =INDEX(D5:D12,MATCH(N4,H5:H12,0)) -> 8
A7: Persona | B7: =IF(N4=0,"",INDEX(AI_INTENT_DB!G:G,N6)) -> Supervisor | D7: 7 | E7: =AI_INTENT_DB!A7 -> INV-001 | F7: =IF(OR(ISNUMBER(SEARCH(LOWER(AI_INTENT_DB!B7),LOWER(ASK_AI!$B$5))),ISNUMBER(SEARCH(LOWER(AI_INTENT_DB!C7),LOWER(ASK_AI!$B$5))),ISNUMBER(SEARCH(LOWER(AI_INTENT_DB!D7),LOWER(ASK_AI!$B$5))),ISNUMBER(SEARCH(LOWER(AI_INTENT_DB!E7),LOWER(ASK_AI!$B$5)))),1,0) -> 0 | G7: =VALUE(SUBSTITUTE(AI_INTENT_DB!I7,"%","")) -> 98 | H7: =F7*G7 -> 0 | I7: =AI_INTENT_DB!F7 -> Find Pallet / LPN | J7: =AI_INTENT_DB!H7 -> Inventory | K7: =AI_INTENT_DB!G7 -> Operative
A8: Domain | B8: =IF(N4=0,"",INDEX(AI_INTENT_DB!H:H,N6)) -> Picking | D8: 8 | E8: =AI_INTENT_DB!A8 -> PCK-001 | F8: =IF(OR(ISNUMBER(SEARCH(LOWER(AI_INTENT_DB!B8),LOWER(ASK_AI!$B$5))),ISNUMBER(SEARCH(LOWER(AI_INTENT_DB!C8),LOWER(ASK_AI!$B$5))),ISNUMBER(SEARCH(LOWER(AI_INTENT_DB!D8),LOWER(ASK_AI!$B$5))),ISNUMBER(SEARCH(LOWER(AI_INTENT_DB!E8),LOWER(ASK_AI!$B$5)))),1,0) -> 1 | G8: =VALUE(SUBSTITUTE(AI_INTENT_DB!I8,"%","")) -> 95 | H8: =F8*G8 -> 95 | I8: =AI_INTENT_DB!F8 -> Blocked Pick Investigation | J8: =AI_INTENT_DB!H8 -> Picking | K8: =AI_INTENT_DB!G8 -> Supervisor
A9: Explanation | B9: =IF(N4=0,"I could not match that yet. Try: outbound orders, find pallet, blocked pick or replenishment.",INDEX(AI_INTENT_DB!K:K,N6)) -> Investigates open or blocked pick work by work reference, wave, order and source location. | D9: 9 | E9: =AI_INTENT_DB!A9 -> RPL-001 | F9: =IF(OR(ISNUMBER(SEARCH(LOWER(AI_INTENT_DB!B9),LOWER(ASK_AI!$B$5))),ISNUMBER(SEARCH(LOWER(AI_INTENT_DB!C9),LOWER(ASK_AI!$B$5))),ISNUMBER(SEARCH(LOWER(AI_INTENT_DB!D9),LOWER(ASK_AI!$B$5))),ISNUMBER(SEARCH(LOWER(AI_INTENT_DB!E9),LOWER(ASK_AI!$B$5)))),1,0) -> 0 | G9: =VALUE(SUBSTITUTE(AI_INTENT_DB!I9,"%","")) -> 94 | H9: =F9*G9 -> 0 | I9: =AI_INTENT_DB!F9 -> Replenishment Work | J9: =AI_INTENT_DB!H9 -> Replenishment | K9: =AI_INTENT_DB!G9 -> Supervisor
A10: Validation | B10: =IF(N4=0,"No validation available until an intent is matched.",INDEX(AI_INTENT_DB!L:L,N6)) -> WH_ID uses wildcard like '%'. Confirm site pick status values and operation codes before final use. | D10: 10 | E10: =AI_INTENT_DB!A10 -> INB-001 | F10: =IF(OR(ISNUMBER(SEARCH(LOWER(AI_INTENT_DB!B10),LOWER(ASK_AI!$B$5))),ISNUMBER(SEARCH(LOWER(AI_INTENT_DB!C10),LOWER(ASK_AI!$B$5))),ISNUMBER(SEARCH(LOWER(AI_INTENT_DB!D10),LOWER(ASK_AI!$B$5))),ISNUMBER(SEARCH(LOWER(AI_INTENT_DB!E10),LOWER(ASK_AI!$B$5)))),1,0) -> 0 | G10: =VALUE(SUBSTITUTE(AI_INTENT_DB!I10,"%","")) -> 92 | H10: =F10*G10 -> 0 | I10: =AI_INTENT_DB!F10 -> Inbound Staging Dwell | J10: =AI_INTENT_DB!H10 -> Inbound | K10: =AI_INTENT_DB!G10 -> Supervisor
A11: Next Action | B11: =IF(N4=0,"Ask a clearer WMS/reporting question.",INDEX(AI_INTENT_DB!M:M,N6)) -> Filter by order, wave, zone or location. | D11: 11 | E11: =AI_INTENT_DB!A11 -> LOC-001 | F11: =IF(OR(ISNUMBER(SEARCH(LOWER(AI_INTENT_DB!B11),LOWER(ASK_AI!$B$5))),ISNUMBER(SEARCH(LOWER(AI_INTENT_DB!C11),LOWER(ASK_AI!$B$5))),ISNUMBER(SEARCH(LOWER(AI_INTENT_DB!D11),LOWER(ASK_AI!$B$5))),ISNUMBER(SEARCH(LOWER(AI_INTENT_DB!E11),LOWER(ASK_AI!$B$5)))),1,0) -> 0 | G11: =VALUE(SUBSTITUTE(AI_INTENT_DB!I11,"%","")) -> 90 | H11: =F11*G11 -> 0 | I11: =AI_INTENT_DB!F11 -> Empty Locations | J11: =AI_INTENT_DB!H11 -> Locations | K11: =AI_INTENT_DB!G11 -> Supervisor
A12: SQL | B12: =IF(N4=0,"",INDEX(AI_INTENT_DB!J:J,N6)) -> [select top 200 pw.wh_id, pw.wrkref, pw.schbat, pw.ordnum, pw.srcloc, pw.dstloc, pw.pcksts, pw.oprcod from pckwrk_view pw with(nolock) where pw.wh_id like '%' and pw.pcksts not in ('C') order by pw.wrkref] | D12: 12 | E12: =AI_INTENT_DB!A12 -> CNT-001 | F12: =IF(OR(ISNUMBER(SEARCH(LOWER(AI_INTENT_DB!B12),LOWER(ASK_AI!$B$5))),ISNUMBER(SEARCH(LOWER(AI_INTENT_DB!C12),LOWER(ASK_AI!$B$5))),ISNUMBER(SEARCH(LOWER(AI_INTENT_DB!D12),LOWER(ASK_AI!$B$5))),ISNUMBER(SEARCH(LOWER(AI_INTENT_DB!E12),LOWER(ASK_AI!$B$5)))),1,0) -> 0 | G12: =VALUE(SUBSTITUTE(AI_INTENT_DB!I12,"%","")) -> 89 | H12: =F12*G12 -> 0 | I12: =AI_INTENT_DB!F12 -> Cycle Count Report | J12: =AI_INTENT_DB!H12 -> Inventory | K12: =AI_INTENT_DB!G12 -> Manager

Sheet SQL_OUTPUT
A1: Generated SQL
A2: Copy SQL from here into LexEdit / ChatWMS after reviewing validation notes.
A4: Generated SQL
A5: =IFERROR(AI_MATCH_ENGINE!B12,"Type a prompt on ASK_AI") -> [select top 200 pw.wh_id, pw.wrkref, pw.schbat, pw.ordnum, pw.srcloc, pw.dstloc, pw.pcksts, pw.oprcod from pckwrk_view pw with(nolock) where pw.wh_id like '%' and pw.pcksts not in ('C') order by pw.wrkref]
A12: Review before running
A13: 1 | B13: All SQL is wrapped in square brackets for MOCA / Beacon style.
A14: 2 | B14: Warehouse filter defaults to wildcard: wh_id like '%'. Narrow this before production use.
